<?xml version="1.0" encoding="utf-8"?>
<!-- =================================================================================== -->
<!-- |    This document was autogenerated by xacro from propbot.urdf.xacro             | -->
<!-- |    EDITING THIS FILE BY HAND IS NOT RECOMMENDED                                 | -->
<!-- =================================================================================== -->
<!--
Software License Agreement (BSD)

\file      propbot.urdf.xacro
\authors   Paul Bovbel <pbovbel@clearpathrobotics.com>, Devon Ash <dash@clearpathrobotics.com>
\copyright Copyright (c) 2015, Clearpath Robotics, Inc., All rights reserved.

Redistribution and use in source and binary forms, with or without modification, are permitted provided that
the following conditions are met:
 * Redistributions of source code must retain the above copyright notice, this list of conditions and the
   following disclaimer.
 * Redistributions in binary form must reproduce the above copyright notice, this list of conditions and the
   following disclaimer in the documentation and/or other materials provided with the distribution.
 * Neither the name of Clearpath Robotics nor the names of its contributors may be used to endorse or promote
   products derived from this software without specific prior written permission.

THIS SOFTWARE IS PROVIDED BY THE COPYRIGHT HOLDERS AND CONTRIBUTORS "AS IS" AND ANY EXPRESS OR IMPLIED WAR-
RANTIES, INCLUDING, BUT NOT LIMITED TO, THE IMPLIED WARRANTIES OF MERCHANTABILITY AND FITNESS FOR A PARTICULAR
PURPOSE ARE DISCLAIMED. IN NO EVENT SHALL THE COPYRIGHT HOLDER OR CONTRIBUTORS BE LIABLE FOR ANY DIRECT, IN-
DIRECT, INCIDENTAL, SPECIAL, EXEMPLARY, OR CONSEQUENTIAL DAMAGES (INCLUDING, BUT NOT LIMITED TO, PROCUREMENT
OF SUBSTITUTE GOODS OR SERVICES; LOSS OF USE, DATA, OR PROFITS; OR BUSINESS INTERRUPTION) HOWEVER CAUSED AND
ON ANY THEORY OF LIABILITY, WHETHER IN CONTRACT, STRICT LIABILITY, OR TORT (INCLUDING NEGLIGENCE OR OTHERWISE)
ARISING IN ANY WAY OUT OF THE USE OF THIS SOFTWARE, EVEN IF ADVISED OF THE POSSIBILITY OF SUCH DAMAGE.
-->
<!-- NOTES

* All values are in metric (m, kg)
* Specific robot structure values extracted from URDF exported from Solidworks

-->
<robot name="propbot">
  <!-- height of the bottom battery plate from the ground -->
  <material name="aluminum">
    <color rgba="0.5 0.5 0.5 1"/>
  </material>
  <material name="plastic">
    <color rgba="0.1 0.1 0.1 1"/>
  </material>
  <!-- offset from the center -->
  <!-- distance from the origin to the front of the robot -->
  <!-- 
  ***********************************************************************************************
  Linking and Joint Specification
  ***********************************************************************************************
  The various links and joints are created and put together
  -->
  <!-- 
  Base Link
  ======================================================================
  -->
  <!-- Base link is the center of the robot's bottom plate -->
  <link name="base_link">
    <visual>
      <origin rpy="0 0 -1.57079632679" xyz="0 0 0.1369"/>
      <geometry>
        <mesh filename="package://propbot_description/meshes/propbot_base_link.STL"/>
      </geometry>
    </visual>
    <collision>
      <origin rpy="0 0 -1.57079632679" xyz="0 0.098175 0.034225"/>
      <geometry>
        <box size="0.982 0.8278 0.06845"/>
      </geometry>
    </collision>
  </link>
  <!-- Set base_link colour in Gazebo -->
  <gazebo reference="base_link">
    <material>Gazebo/Red</material>
  </gazebo>
  <!-- Base footprint is on the ground under the robot -->
  <link name="base_footprint"/>
  <joint name="base_footprint_joint" type="fixed">
    <origin rpy="0 0 0" xyz="0 0 0.0"/>
    <parent link="base_link"/>
    <child link="base_footprint"/>
  </joint>
  <!-- 
  Inertial Link
  ======================================================================
  Interial link stores the robot's inertial information 
  For this case, the mass, origin, and inertia values of the main chassis is used
  -->
  <link name="inertial_link">
    <inertial>
      <mass value="73.4517985951"/>
      <origin rpy="-1.57079632679 -1.57079632679 0" xyz="0.027 -0.01 0.42243"/>
      <inertia ixx="1.81281457357" ixy="0.00100397183552" ixz="0.0" iyy="1.69827214398" iyz="0.0" izz="0.894962007862"/>
    </inertial>
  </link>
  <joint name="inertial_joint" type="fixed">
    <origin rpy="0 0 0" xyz="0 0 0"/>
    <parent link="base_link"/>
    <child link="inertial_link"/>
  </joint>
  <!-- 
  IMU Link
  ======================================================================
  IMU Link is the standard mounting position for the UM6 IMU.
  Can be modified with environment variables in /etc/ros/setup.bash 
  -->
  <link name="imu_link"/>
  <joint name="imu_joint" type="fixed">
    <origin rpy="0 -1.5708 3.1416" xyz="0.19 0 0.149"/>
    <parent link="base_link"/>
    <child link="imu_link"/>
  </joint>
  <gazebo reference="imu_link">
  </gazebo>
  <link name="front_right_wheel_link">
    <!-- Following values extracted from URDF exported from Solidworks -->
    <inertial>
      <mass value="2.96542"/>
      <origin xyz="0 0 0"/>
      <inertia ixx="0.01875" ixy="0" ixz="0" iyy="0.01012" iyz="0" izz="0"/>
    </inertial>
    <visual>
      <origin rpy="0 0 0" xyz="0 0 0"/>
      <geometry>
        <mesh filename="package://propbot_description/meshes/propbot_wheel.STL"/>
      </geometry>
      <material name="wheel_material">
        <color rgba="0.109804 0.109804 0.109804 1"/>
      </material>
    </visual>
    <collision>
      <origin rpy="0 0 0" xyz="0 0 0"/>
      <geometry>
        <cylinder length="0.08975" radius="0.127"/>
      </geometry>
    </collision>
  </link>
  <gazebo reference="front_right_wheel_link">
    <mu1 value="100.0"/>
    <mu2 value="100.0"/>
    <kp value="10000000.0"/>
    <kd value="1.0"/>
    <fdir1 value="1 0 0"/>
    <material>Gazebo/Black</material>
  </gazebo>
  <joint name="front_right_wheel" type="continuous">
    <parent link="base_link"/>
    <child link="front_right_wheel_link"/>
    <origin rpy="0 0 -1.57079632679" xyz="0.4599 -0.444875 0.127"/>
    <axis rpy="0 0 0" xyz="-1 0 0"/>
  </joint>
  <transmission name="front_right_wheel_trans" type="SimpleTransmission">
    <type>transmission_interface/SimpleTransmission</type>
    <actuator name="front_right_wheel_motor">
      <mechanicalReduction>1</mechanicalReduction>
    </actuator>
    <joint name="front_right_wheel">
      <hardwareInterface>hardware_interface/VelocityJointInterface</hardwareInterface>
    </joint>
  </transmission>
  <link name="rear_right_wheel_link">
    <!-- Following values extracted from URDF exported from Solidworks -->
    <inertial>
      <mass value="2.96542"/>
      <origin xyz="0 0 0"/>
      <inertia ixx="0.01875" ixy="0" ixz="0" iyy="0.01012" iyz="0" izz="0"/>
    </inertial>
    <visual>
      <origin rpy="0 0 0" xyz="0 0 0"/>
      <geometry>
        <mesh filename="package://propbot_description/meshes/propbot_wheel.STL"/>
      </geometry>
      <material name="wheel_material">
        <color rgba="0.109804 0.109804 0.109804 1"/>
      </material>
    </visual>
    <collision>
      <origin rpy="0 0 0" xyz="0 0 0"/>
      <geometry>
        <cylinder length="0.08975" radius="0.127"/>
      </geometry>
    </collision>
  </link>
  <gazebo reference="rear_right_wheel_link">
    <mu1 value="100.0"/>
    <mu2 value="100.0"/>
    <kp value="10000000.0"/>
    <kd value="1.0"/>
    <fdir1 value="1 0 0"/>
    <material>Gazebo/Black</material>
  </gazebo>
  <joint name="rear_right_wheel" type="continuous">
    <parent link="base_link"/>
    <child link="rear_right_wheel_link"/>
    <origin rpy="0 0 -1.57079632679" xyz="-0.375233333333 -0.444875 0.127"/>
    <axis rpy="0 0 0" xyz="-1 0 0"/>
  </joint>
  <transmission name="rear_right_wheel_trans" type="SimpleTransmission">
    <type>transmission_interface/SimpleTransmission</type>
    <actuator name="rear_right_wheel_motor">
      <mechanicalReduction>1</mechanicalReduction>
    </actuator>
    <joint name="rear_right_wheel">
      <hardwareInterface>hardware_interface/VelocityJointInterface</hardwareInterface>
    </joint>
  </transmission>
  <link name="front_left_wheel_link">
    <!-- Following values extracted from URDF exported from Solidworks -->
    <inertial>
      <mass value="2.96542"/>
      <origin xyz="0 0 0"/>
      <inertia ixx="0.01875" ixy="0" ixz="0" iyy="0.01012" iyz="0" izz="0"/>
    </inertial>
    <visual>
      <origin rpy="0 0 0" xyz="0 0 0"/>
      <geometry>
        <mesh filename="package://propbot_description/meshes/propbot_wheel.STL"/>
      </geometry>
      <material name="wheel_material">
        <color rgba="0.109804 0.109804 0.109804 1"/>
      </material>
    </visual>
    <collision>
      <origin rpy="0 0 0" xyz="0 0 0"/>
      <geometry>
        <cylinder length="0.08975" radius="0.127"/>
      </geometry>
    </collision>
  </link>
  <gazebo reference="front_left_wheel_link">
    <mu1 value="100.0"/>
    <mu2 value="100.0"/>
    <kp value="10000000.0"/>
    <kd value="1.0"/>
    <fdir1 value="1 0 0"/>
    <material>Gazebo/Black</material>
  </gazebo>
  <joint name="front_left_wheel" type="continuous">
    <parent link="base_link"/>
    <child link="front_left_wheel_link"/>
    <origin rpy="0 0 -1.57079632679" xyz="0.4599 0.444875 0.127"/>
    <axis rpy="0 0 0" xyz="-1 0 0"/>
  </joint>
  <transmission name="front_left_wheel_trans" type="SimpleTransmission">
    <type>transmission_interface/SimpleTransmission</type>
    <actuator name="front_left_wheel_motor">
      <mechanicalReduction>1</mechanicalReduction>
    </actuator>
    <joint name="front_left_wheel">
      <hardwareInterface>hardware_interface/VelocityJointInterface</hardwareInterface>
    </joint>
  </transmission>
  <link name="rear_left_wheel_link">
    <!-- Following values extracted from URDF exported from Solidworks -->
    <inertial>
      <mass value="2.96542"/>
      <origin xyz="0 0 0"/>
      <inertia ixx="0.01875" ixy="0" ixz="0" iyy="0.01012" iyz="0" izz="0"/>
    </inertial>
    <visual>
      <origin rpy="0 0 0" xyz="0 0 0"/>
      <geometry>
        <mesh filename="package://propbot_description/meshes/propbot_wheel.STL"/>
      </geometry>
      <material name="wheel_material">
        <color rgba="0.109804 0.109804 0.109804 1"/>
      </material>
    </visual>
    <collision>
      <origin rpy="0 0 0" xyz="0 0 0"/>
      <geometry>
        <cylinder length="0.08975" radius="0.127"/>
      </geometry>
    </collision>
  </link>
  <gazebo reference="rear_left_wheel_link">
    <mu1 value="100.0"/>
    <mu2 value="100.0"/>
    <kp value="10000000.0"/>
    <kd value="1.0"/>
    <fdir1 value="1 0 0"/>
    <material>Gazebo/Black</material>
  </gazebo>
  <joint name="rear_left_wheel" type="continuous">
    <parent link="base_link"/>
    <child link="rear_left_wheel_link"/>
    <origin rpy="0 0 -1.57079632679" xyz="-0.375233333333 0.444875 0.127"/>
    <axis rpy="0 0 0" xyz="-1 0 0"/>
  </joint>
  <transmission name="rear_left_wheel_trans" type="SimpleTransmission">
    <type>transmission_interface/SimpleTransmission</type>
    <actuator name="rear_left_wheel_motor">
      <mechanicalReduction>1</mechanicalReduction>
    </actuator>
    <joint name="rear_left_wheel">
      <hardwareInterface>hardware_interface/VelocityJointInterface</hardwareInterface>
    </joint>
  </transmission>
  <link name="left_wheel_link">
    <!-- Following values extracted from URDF exported from Solidworks -->
    <inertial>
      <mass value="2.96542"/>
      <origin xyz="0 0 0"/>
      <inertia ixx="0.01875" ixy="0" ixz="0" iyy="0.01012" iyz="0" izz="0"/>
    </inertial>
    <visual>
      <origin rpy="0 0 0" xyz="0 0 0"/>
      <geometry>
        <mesh filename="package://propbot_description/meshes/propbot_wheel.STL"/>
      </geometry>
      <material name="wheel_material">
        <color rgba="0.109804 0.109804 0.109804 1"/>
      </material>
    </visual>
    <collision>
      <origin rpy="0 0 0" xyz="0 0 0"/>
      <geometry>
        <cylinder length="0.08975" radius="0.127"/>
      </geometry>
    </collision>
  </link>
  <gazebo reference="left_wheel_link">
    <mu1 value="100.0"/>
    <mu2 value="100.0"/>
    <kp value="10000000.0"/>
    <kd value="1.0"/>
    <fdir1 value="1 0 0"/>
    <material>Gazebo/Black</material>
  </gazebo>
  <joint name="left_wheel" type="continuous">
    <parent link="base_link"/>
    <child link="left_wheel_link"/>
    <origin rpy="0 0 -1.57079632679" xyz="0.027 0.444875 0.1397"/>
    <mimic joint="rear_left_wheel"/>
    <axis rpy="0 0 0" xyz="-1 0 0"/>
  </joint>
  <link name="right_wheel_link">
    <!-- Following values extracted from URDF exported from Solidworks -->
    <inertial>
      <mass value="2.96542"/>
      <origin xyz="0 0 0"/>
      <inertia ixx="0.01875" ixy="0" ixz="0" iyy="0.01012" iyz="0" izz="0"/>
    </inertial>
    <visual>
      <origin rpy="0 0 0" xyz="0 0 0"/>
      <geometry>
        <mesh filename="package://propbot_description/meshes/propbot_wheel.STL"/>
      </geometry>
      <material name="wheel_material">
        <color rgba="0.109804 0.109804 0.109804 1"/>
      </material>
    </visual>
    <collision>
      <origin rpy="0 0 0" xyz="0 0 0"/>
      <geometry>
        <cylinder length="0.08975" radius="0.127"/>
      </geometry>
    </collision>
  </link>
  <gazebo reference="right_wheel_link">
    <mu1 value="100.0"/>
    <mu2 value="100.0"/>
    <kp value="10000000.0"/>
    <kd value="1.0"/>
    <fdir1 value="1 0 0"/>
    <material>Gazebo/Black</material>
  </gazebo>
  <joint name="right_wheel" type="continuous">
    <parent link="base_link"/>
    <child link="right_wheel_link"/>
    <origin rpy="0 0 -1.57079632679" xyz="0.027 -0.444875 0.1397"/>
    <mimic joint="rear_right_wheel"/>
    <axis rpy="0 0 0" xyz="-1 0 0"/>
  </joint>
  <!-- 
    Chassis
    ======================================================================
    -->
  <!-- Spawn Propbot chassis -->
  <link name="chassis_link">
    <visual>
      <origin rpy="1.57079632679 0 -1.57079632679" xyz="0.491 0 0.1171"/>
      <geometry>
        <mesh filename="package://propbot_description/meshes/propbot_chassis.STL"/>
      </geometry>
    </visual>
  </link>
  <!-- Set chassis colour in Gazebo -->
  <gazebo reference="chassis_link">
    <material>Gazebo/Red</material>
  </gazebo>
  <!-- Attach chassis to the robot -->
  <joint name="chassis_joint" type="fixed">
    <parent link="base_link"/>
    <child link="chassis_link"/>
  </joint>
  <!-- 
    Top plate
    ======================================================================
    A tiny plate use to link the sensors to the robot
    -->
  <!-- Spawn the top plate -->
  <link name="top_plate_link">
    <visual>
      <origin rpy="0 0 0" xyz="0.491 -0.3869 0.37545"/>
      <geometry>
        <box size="0.01 0.01 0.001"/>
      </geometry>
      <material name="wheel_material">
        <color rgba="0.25 0.25 0.75 0"/>
      </material>
    </visual>
  </link>
  <!-- Attach top plate to chassis -->
  <joint name="top_plate_chassis_joint" type="fixed">
    <parent link="chassis_link"/>
    <child link="top_plate_link"/>
    <origin rpy="0 0 0" xyz="0 0.387525 0.001"/>
  </joint>
  <!-- 
  ***********************************************************************************************
  Gazebo Specifications
  ***********************************************************************************************
  -->
  <!-- Motion controller -->
  <gazebo>
    <plugin filename="libgazebo_ros_control.so" name="gazebo_ros_control">
      <robotNamespace>/</robotNamespace>
    </plugin>
  </gazebo>
  <!-- IMU controller -->
  <gazebo>
    <plugin filename="libhector_gazebo_ros_imu.so" name="imu_controller">
      <robotNamespace>/</robotNamespace>
      <updateRate>50.0</updateRate>
      <bodyName>base_link</bodyName>
      <topicName>imu/data</topicName>
      <accelDrift>0.005 0.005 0.005</accelDrift>
      <accelGaussianNoise>0.005 0.005 0.005</accelGaussianNoise>
      <rateDrift>0.005 0.005 0.005 </rateDrift>
      <rateGaussianNoise>0.005 0.005 0.005 </rateGaussianNoise>
      <headingDrift>0.005</headingDrift>
      <headingGaussianNoise>0.005</headingGaussianNoise>
    </plugin>
  </gazebo>
  <!-- GPS controller -->
  <gazebo>
    <plugin filename="libhector_gazebo_ros_gps.so" name="gps_controller">
      <robotNamespace>/</robotNamespace>
      <updateRate>40</updateRate>
      <bodyName>base_link</bodyName>
      <frameId>base_link</frameId>
      <topicName>navsat/fix</topicName>
      <velocityTopicName>navsat/vel</velocityTopicName>
      <referenceLatitude>49.9</referenceLatitude>
      <referenceLongitude>8.9</referenceLongitude>
      <referenceHeading>0</referenceHeading>
      <referenceAltitude>0</referenceAltitude>
      <drift>0.0001 0.0001 0.0001</drift>
    </plugin>
  </gazebo>
</robot>

